<?xml version="1.0" encoding="UTF-8"?>
<testng-results ignored="0" total="1" passed="0" failed="1" skipped="0">
  <reporter-output>
  </reporter-output>
  <suite started-at="2024-09-16T16:10:55 IST" name="Suite" finished-at="2024-09-16T16:14:19 IST" duration-ms="203853">
    <groups>
    </groups>
    <test started-at="2024-09-16T16:10:55 IST" name="Test" finished-at="2024-09-16T16:14:19 IST" duration-ms="203853">
      <class name="testPackage.CheckWebsiteTestCaase">
        <test-method is-config="true" signature="setup()[pri:0, instance:testPackage.CheckWebsiteTestCaase@3c19aaa5]" started-at="2024-09-16T16:10:55 IST" name="setup" finished-at="2024-09-16T16:10:57 IST" duration-ms="2050" status="PASS">
          <reporter-output>
          </reporter-output>
        </test-method> <!-- setup -->
        <test-method signature="verifyWebsiteSecurity()[pri:0, instance:testPackage.CheckWebsiteTestCaase@3c19aaa5]" started-at="2024-09-16T16:10:57 IST" name="verifyWebsiteSecurity" finished-at="2024-09-16T16:14:17 IST" duration-ms="200453" status="FAIL">
          <exception class="java.lang.AssertionError">
            <message>
              <![CDATA[One or more websites are not secure.]]>
            </message>
            <full-stacktrace>
              <![CDATA[java.lang.AssertionError: One or more websites are not secure.
at org.testng.Assert.fail(Assert.java:110)
at testPackage.CheckWebsiteTestCaase.verifyWebsiteSecurity(CheckWebsiteTestCaase.java:66)
at java.base/jdk.internal.reflect.DirectMethodHandleAccessor.invoke(DirectMethodHandleAccessor.java:103)
at java.base/java.lang.reflect.Method.invoke(Method.java:580)
at org.testng.internal.invokers.MethodInvocationHelper.invokeMethod(MethodInvocationHelper.java:139)
at org.testng.internal.invokers.TestInvoker.invokeMethod(TestInvoker.java:677)
at org.testng.internal.invokers.TestInvoker.invokeTestMethod(TestInvoker.java:221)
at org.testng.internal.invokers.MethodRunner.runInSequence(MethodRunner.java:50)
at org.testng.internal.invokers.TestInvoker$MethodInvocationAgent.invoke(TestInvoker.java:969)
at org.testng.internal.invokers.TestInvoker.invokeTestMethods(TestInvoker.java:194)
at org.testng.internal.invokers.TestMethodWorker.invokeTestMethods(TestMethodWorker.java:148)
at org.testng.internal.invokers.TestMethodWorker.run(TestMethodWorker.java:128)
at java.base/java.util.ArrayList.forEach(ArrayList.java:1596)
at org.testng.TestRunner.privateRun(TestRunner.java:829)
at org.testng.TestRunner.run(TestRunner.java:602)
at org.testng.SuiteRunner.runTest(SuiteRunner.java:437)
at org.testng.SuiteRunner.runSequentially(SuiteRunner.java:431)
at org.testng.SuiteRunner.privateRun(SuiteRunner.java:391)
at org.testng.SuiteRunner.run(SuiteRunner.java:330)
at org.testng.SuiteRunnerWorker.runSuite(SuiteRunnerWorker.java:52)
at org.testng.SuiteRunnerWorker.run(SuiteRunnerWorker.java:95)
at org.testng.TestNG.runSuitesSequentially(TestNG.java:1256)
at org.testng.TestNG.runSuitesLocally(TestNG.java:1176)
at org.testng.TestNG.runSuites(TestNG.java:1099)
at org.testng.TestNG.run(TestNG.java:1067)
at org.testng.remote.AbstractRemoteTestNG.run(AbstractRemoteTestNG.java:115)
at org.testng.remote.RemoteTestNG.initAndRun(RemoteTestNG.java:251)
at org.testng.remote.RemoteTestNG.main(RemoteTestNG.java:77)
]]>
            </full-stacktrace>
          </exception> <!-- java.lang.AssertionError -->
          <reporter-output>
          </reporter-output>
        </test-method> <!-- verifyWebsiteSecurity -->
        <test-method is-config="true" signature="teardown()[pri:0, instance:testPackage.CheckWebsiteTestCaase@3c19aaa5]" started-at="2024-09-16T16:14:17 IST" name="teardown" finished-at="2024-09-16T16:14:19 IST" duration-ms="1270" status="PASS">
          <reporter-output>
          </reporter-output>
        </test-method> <!-- teardown -->
      </class> <!-- testPackage.CheckWebsiteTestCaase -->
    </test> <!-- Test -->
  </suite> <!-- Suite -->
</testng-results>
